Workbook

Sheet Inhoud
A1: Inhoudsopgaven
A3: Pagina eBook | B3: Onderwerp | C3: Snelkoppeling | D3: Instructie
A4: 8 | B4: Doelbepaling | C4: Doelbepaling | D4: Vul in de open velden de waarden in
A5: 10 | B5: Dag 1 | C5: Dag 1 | D5: Oefening 1 t/m 3: vul in de open velden de waarden in. Oefening 4: klik op "oefening 4 en vul de waarde in het nieuwe tabblad in.
A6: 17 | B6: Dag 2 | C6: Dag 2 | D6: Oefening 1 en 2: vul in de open velden de waarden in. Oefening 3: klik op "oefening 3" en vul de waarde in in het veld
A7: 18 | B7: Dag 2 | C7: Dag 3 | D7: Oefening 1 en 2: vul in de open velden de waarden in. Oefening 3: klik op "oefening 3" en vul de waarde in in het veld
A8: 24 | B8: Dag 4 | C8: Dag 4 | D8: Oefening 1 en 2: vul in de open velden de waarden in. Oefening 3: klik op "oefening 3" en vul de waarde in in het veld

Sheet Doelbepaling
B1: Terug naar Inhoud
A2: Doelbepalingen - Wat wil je bereiken
A3: Wat wil je bereiken
A6: Wat is je streefdoel na 4 trainingsweken?
A7: Procesdoel 1
A9: Procesdoel 2
A11: Resultaatdoel 1
A13: Resultaatdoel 2
A15: Effectief trainen begint bij een plan!

Sheet Dag 1
B1: Terug naar Inhoud
A2: Dag 1 - Rust, Ritme, Richting
A3: Oefening 1
A4: Score Ronde 1
A5: Score Ronde 2
A6: Streefdoel
A7: Hoe ga je dit doel bereiken?
A9: Oefening 2
A10: Score aantal darts
A11: Streefdoel
A12: Hoe ga je dit doel bereiken?
A14: Oefening 3
A15: Score 1 | B15: 16
A16: Score 2 | B16: 13
A17: Score 3 | B17: 15
A18: Gemiddelde (na streep) | B18: =ROUND((SUM(B15:B17)/3),1) -> 14.7
A19: Oefening 4
A20: Score 1 | B20: =Score!B12 -> 0
A21: Score 2 | B21: =Score!D12 -> 0
A22: Score 3 | B22: =Score!F12 -> 0
A23: Score 4 | B23: =Score!H12 -> 0
A24: Score 5 | B24: =Score!J12 -> 0
A25: Gemiddelde (na streep) | B25: =ROUND(Score!M6,1) -> 0
A26: Datum
A27: Streefdoel
A28: Hoe ga je dit doel bereiken?
A39: Oefening 5
A40: Welke dubbels gingen goed?
A41: Met welke dubbels had je moeite
A42: Tot waar ben je gekomen (15 min)
A43: Streefdoel
A44: Hoe ga je dit doel bereiken?
A46: Oefening 6
A47: Hoe ver ben je gekomen in 30 min
A48: Hoogste score bereikt
... A67: Effectief trainen begint bij een plan!

Sheet Dag 2
B1: Terug naar Inhoud
A2: Dag 2 - Herhaling & wedstrijddruk
A3: Oefening 1
A4: Score aantal darts
A5: Oefening 2
A6: Score 1
A7: Score 2
A8: Score 3
A9: Gemiddelde (na streep) | B9: =ROUND((SUM(B6:B8)/3),1) -> 0
A10: Oefening 3
A11: Score 1 | B11: =Score!B25 -> 0
A12: Score 2 | B12: =Score!D25 -> 0
A13: Score 3 | B13: =Score!F25 -> 0
A14: Score 4 | B14: =Score!H25 -> 0
A15: Score 5 | B15: =Score!J25 -> 0
A16: Nieuwe ijkscore | B16: =ROUND(Score!M19,1) -> 0
A17: Datum
A18: Oefening 4
A19: Streefscore
A20: Behaalde score
A21: Oefening 5
A22: Score Leg 1
A23: Score Leg 2
A24: Score Leg 3
A25: Score Leg 4
A26: Score Leg 5
A27: Score Leg 6
A28: Gemiddelde (na streep) | B28: =ROUND((SUM(B22:B27)-MIN(B22:B27)-MAX(B22:B27))/4,1) -> 0
A29: Eindscore | B29: Win - Verlies
B30: -
A31: Oefening 6
A32: Eindscore
A43: Reflectie Dag 2
A44: Hoe voelde je lichaam vandaag bij het ingooien?
A46: Was je focus beter, slechter of hetzelfde als gisteren? Waarom?
A48: Welke oefening voelde het meest als 'wedstrijd'?
A50: Wat zegt de uitslag van je wedstrijdvorm over je niveau
A52: Heb je iets gedaan wat gisteren nog niet lukte?
A54: Welke mentale strategie hielp je het meest tijdens drukmomenten?
A56: Wat neem je mee naar dag 3?
...

Sheet Dag 3
B1: Terug naar Inhoud
A2: Dag 3 - Verdieping & Variatie
A3: Oefening 1
A4: Score op de 20, Poging 1
A5: Score op de 20, Poging 2
A6: Score op de 20, Poging 3
A7: Score op de 19, Poging 1
A8: Score op de 19, Poging 2
A9: Score op de 19, Poging 3
A10: Score op de 20/19/18, Poging 1
A11: Score op de 20/19/18, Poging 2
A12: Score op de 20/19/18, Poging 3
A13: Gemiddelde (na streep) | B13: =ROUND((SUM(B4:B12)-MIN(B4:B12)-MAX(B4:B12))/9,1) -> 0
A14: Oefening 2
A15: Rondje singles score
A16: Oefening 3
A17: Welke dubbels gingen goed?
A18: Met welke dubbels had je moeite
A19: Kijk naar je streefdoel (Dag 1, oefening 5)
A20: Oefening 4
A21: Score 1 | B21: =Score!B38 -> 0
A22: Score 2 | B22: =Score!D38 -> 0
A23: Score 3 | B23: =Score!F38 -> 0
A24: Score 4 | B24: =Score!H38 -> 0
A25: Score 5 | B25: =Score!J38 -> 0
A26: Nieuwe ijkscore | B26: =ROUND(Score!M32,1) -> 0
A27: Datum
A28: Oefening 5
A29: Hoogste Finish gehaald
A30: Oefening 6
A31: De uitslag
A43: Reflectie Dag 3
A44: Welke oefening voelde vandaag het scherpst?
A46: Hoe goed lukt het om te variëren zonder focus te verliezen?
A48: Wat vond je moeilijk?
A50: Heb je vooruitgang geboekt op de scorers of finishes t.o.v. dag 2?
A52: Wat wil je op dag 4 vasthouden of verbeteren?
A54: Welke mentale strategie hielp je het meest tijdens drukmomenten?
A57: Effectief trainen begint bij een plan!

Sheet Dag 4
B1: Terug naar Inhoud
A2: Dag 4 - Wedstrijd of Vrije Training
A3: Oefening 1
A4: Potje 1 - Resultaat | B4: Gewonnen / verloren
A5: Potje 1 - Aantal darts nodig
A6: Potje 2 - Resultaat | B6: Gewonnen / verloren
A7: Potje 2 - Aantal darts nodig
A8: Potje 3 - Resultaat | B8: Gewonnen / verloren
A9: Potje 3 - Aantal darts nodig
A10: Potje 4 - Resultaat | B10: Gewonnen / verloren
A11: Potje 4 - Aantal darts nodig
A12: Potje 5 - Resultaat | B12: Gewonnen / verloren
A13: Potje 5 - Aantal darts nodig
A14: Oefening 2
A15: Score 1 | B15: =Score!B38 -> 0
A16: Score 2 | B16: =Score!D38 -> 0
A17: Score 3 | B17: =Score!F38 -> 0
A18: Score 4 | B18: =Score!H38 -> 0
A19: Score 5 | B19: =Score!J38 -> 0
A20: Nieuwe ijkscore | B20: =ROUND(Score!M32,1) -> 0
A21: Datum
A22: Oefening 3
A23: Hoogste Finish gehaald (na 1 uur)
A24: Wat doe je om in Zone 1 te komen?
A36: Slotreflectie
A37: Wat heb je geleerd van deze 4 dagen?
A39: Waar zie je je grootste groei?
A41: Wat wil je blijven herhalen?
A43: Wat is je volgende stap?
A45: Effectief trainen begint bij een plan!

Sheet Score
A1: Dag 1 | B1: Oefening 4 | F1: Datum: | H1: dd/mm/jjjj | I1: Terug naar Dag 1 | U1: Datum: | W1: 46978 | X1: Terug naar Dag 1
A2: 1 | C2: 1 | E2: 1 | G2: 1 | I2: 1 | L2: Totaal | M2: =SUM(B12:J12) -> 0 | P2: 1 | R2: 1 | T2: 1 | V2: 1 | X2: 1 | AA2: Totaal | AB2: =SUM(Q12:Y12) -> 0
A3: 2 | C3: 2 | E3: 2 | G3: 2 | I3: 2 | L3: Laagste | M3: =MIN(B12:J12) -> 0 | P3: 2 | R3: 2 | T3: 2 | V3: 2 | X3: 2 | AA3: Laagste | AB3: =MIN(Q12:Y12) -> 0
A4: 3 | C4: 3 | E4: 3 | G4: 3 | I4: 3 | L4: Hoogste | M4: =MAX(B12:J12) -> 0 | P4: 3 | R4: 3 | T4: 3 | V4: 3 | X4: 3 | AA4: Hoogste | AB4: =MAX(Q12:Y12) -> 0
A5: 4 | C5: 4 | E5: 4 | G5: 4 | I5: 4 | L5: Subtotaal | M5: =M2-M3-M4 -> 0 | P5: 4 | R5: 4 | T5: 4 | V5: 4 | X5: 4 | AA5: Subtotaal | AB5: =AB2-AB3-AB4 -> 0
A6: 5 | C6: 5 | E6: 5 | G6: 5 | I6: 5 | L6: Gemiddelde | M6: =ROUND(M5/30,1) -> 0 | P6: 5 | R6: 5 | T6: 5 | V6: 5 | X6: 5 | AA6: Gemiddelde | AB6: =AB5/30 -> 0
A7: 6 | C7: 6 | E7: 6 | G7: 6 | I7: 6 | L7: Datum | M7: =IF(H1="","",H1) -> dd/mm/jjjj | P7: 6 | R7: 6 | T7: 6 | V7: 6 | X7: 6 | AA7: Datum | AB7: =IF(R1="","",R1)
A8: 7 | C8: 7 | E8: 7 | G8: 7 | I8: 7 | P8: 7 | R8: 7 | T8: 7 | V8: 7 | X8: 7
A9: 8 | C9: 8 | E9: 8 | G9: 8 | I9: 8 | P9: 8 | R9: 8 | T9: 8 | V9: 8 | X9: 8
A10: 9 | C10: 9 | E10: 9 | G10: 9 | I10: 9 | P10: 9 | R10: 9 | T10: 9 | V10: 9 | X10: 9
A11: 10 | C11: 10 | E11: 10 | G11: 10 | I11: 10 | P11: 10 | R11: 10 | T11: 10 | V11: 10 | X11: 10
B12: =SUM(B2:B11) -> 0 | D12: =SUM(D2:D11) -> 0 | F12: =SUM(F2:F11) -> 0 | H12: =SUM(H2:H11) -> 0 | J12: =SUM(J2:J11) -> 0 | L12: Terug naar Dag 1 | Q12: =SUM(Q2:Q11) -> 0 | S12: =SUM(S2:S11) -> 0 | U12: =SUM(U2:U11) -> 0 | W12: =SUM(W2:W11) -> 0 | Y12: =SUM(Y2:Y11) -> 0
A14: Dag 2 | B14: Oefening 3 | F14: Datum: | H14: dd/mm/jjjj | I14: Terug naar Dag 2 | U14: Datum: | W14: 46978 | X14: Terug naar Dag 1
A15: 1 | C15: 1 | E15: 1 | G15: 1 | I15: 1 | L15: Totaal | M15: =SUM(B25:J25) -> 0 | P15: 1 | R15: 1 | T15: 1 | V15: 1 | X15: 1 | AA15: Totaal | AB15: =SUM(Q25:Y25) -> 0
A16: 2 | C16: 2 | E16: 2 | G16: 2 | I16: 2 | L16: Laagste | M16: =MIN(B25:J25) -> 0 | P16: 2 | R16: 2 | T16: 2 | V16: 2 | X16: 2 | AA16: Laagste | AB16: =MIN(Q25:Y25) -> 0
A17: 3 | C17: 3 | E17: 3 | G17: 3 | I17: 3 | L17: Hoogste | M17: =MAX(B25:J25) -> 0 | P17: 3 | R17: 3 | T17: 3 | V17: 3 | X17: 3 | AA17: Hoogste | AB17: =MAX(Q25:Y25) -> 0
A18: 4 | C18: 4 | E18: 4 | G18: 4 | I18: 4 | L18: Subtotaal | M18: =M15-M16-M17 -> 0 | P18: 4 | R18: 4 | T18: 4 | V18: 4 | X18: 4 | AA18: Subtotaal | AB18: =AB15-AB16-AB17 -> 0
A19: 5 | C19: 5 | E19: 5 | G19: 5 | I19: 5 | L19: Gemiddelde | M19: =M18/30 -> 0 | P19: 5 | R19: 5 | T19: 5 | V19: 5 | X19: 5 | AA19: Gemiddelde | AB19: =AB18/30 -> 0
A20: 6 | C20: 6 | E20: 6 | G20: 6 | I20: 6 | L20: Datum | M20: =IF(H14="","",H14) -> dd/mm/jjjj | P20: 6 | R20: 6 | T20: 6 | V20: 6 | X20: 6 | AA20: Datum | AB20: =IF(R14="","",R14)
A21: 7 | C21: 7 | E21: 7 | G21: 7 | I21: 7 | P21: 7 | R21: 7 | T21: 7 | V21: 7 | X21: 7
A22: 8 | C22: 8 | E22: 8 | G22: 8 | I22: 8 | P22: 8 | R22: 8 | T22: 8 | V22: 8 | X22: 8
A23: 9 | C23: 9 | E23: 9 | G23: 9 | I23: 9 | P23: 9 | R23: 9 | T23: 9 | V23: 9 | X23: 9
A24: 10 | C24: 10 | E24: 10 | G24: 10 | I24: 10 | P24: 10 | R24: 10 | T24: 10 | V24: 10 | X24: 10
B25: =SUM(B15:B24) -> 0 | D25: =SUM(D15:D24) -> 0 | F25: =SUM(F15:F24) -> 0 | H25: =SUM(H15:H24) -> 0 | J25: =SUM(J15:J24) -> 0 | L25: Terug naar Dag 2 | Q25: =SUM(Q15:Q24) -> 0 | S25: =SUM(S15:S24) -> 0 | U25: =SUM(U15:U24) -> 0 | W25: =SUM(W15:W24) -> 0 | Y25: =SUM(Y15:Y24) -> 0
A27: Dag 3 | B27: Oefening 4 | F27: Datum: | H27: dd/mm/jjjj | I27: Terug naar Dag 3
A28: 1 | C28: 1 | E28: 1 | G28: 1 | I28: 1 | L28: Totaal | M28: =SUM(B38:J38) -> 0 | U28: Datum: | W28: 46978 | X28: Terug naar Dag 1
A29: 2 | C29: 2 | E29: 2 | G29: 2 | I29: 2 | L29: Laagste | M29: =MIN(B38:J38) -> 0 | P29: 1 | R29: 1 | T29: 1 | V29: 1 | X29: 1 | AA29: Totaal | AB29: =SUM(Q39:Y39) -> 0
A30: 3 | C30: 3 | E30: 3 | G30: 3 | I30: 3 | L30: Hoogste | M30: =MAX(B38:J38) -> 0 | P30: 2 | R30: 2 | T30: 2 | V30: 2 | X30: 2 | AA30: Laagste | AB30: =MIN(Q39:Y39) -> 0
A31: 4 | C31: 4 | E31: 4 | G31: 4 | I31: 4 | L31: Subtotaal | M31: =M28-M29-M30 -> 0 | P31: 3 | R31: 3 | T31: 3 | V31: 3 | X31: 3 | AA31: Hoogste | AB31: =MAX(Q39:Y39) -> 0
A32: 5 | C32: 5 | E32: 5 | G32: 5 | I32: 5 | L32: Gemiddelde | M32: =M31/30 -> 0 | P32: 4 | R32: 4 | T32: 4 | V32: 4 | X32: 4 | AA32: Subtotaal | AB32: =AB29-AB30-AB31 -> 0
A33: 6 | C33: 6 | E33: 6 | G33: 6 | I33: 6 | L33: Datum | M33: =IF(H27="","",H27) -> dd/mm/jjjj | P33: 5 | R33: 5 | T33: 5 | V33: 5 | X33: 5 | AA33: Gemiddelde | AB33: =AB32/30 -> 0
A34: 7 | C34: 7 | E34: 7 | G34: 7 | I34: 7 | P34: 6 | R34: 6 | T34: 6 | V34: 6 | X34: 6 | AA34: Datum | AB34: =IF(R28="","",R28)
A35: 8 | C35: 8 | E35: 8 | G35: 8 | I35: 8 | P35: 7 | R35: 7 | T35: 7 | V35: 7 | X35: 7
A36: 9 | C36: 9 | E36: 9 | G36: 9 | I36: 9 | P36: 8 | R36: 8 | T36: 8 | V36: 8 | X36: 8
A37: 10 | C37: 10 | E37: 10 | G37: 10 | I37: 10 | P37: 9 | R37: 9 | T37: 9 | V37: 9 | X37: 9
B38: =SUM(B28:B37) -> 0 | D38: =SUM(D28:D37) -> 0 | F38: =SUM(F28:F37) -> 0 | H38: =SUM(H28:H37) -> 0 | J38: =SUM(J28:J37) -> 0 | L38: Terug naar Dag 3 | P38: 10 | R38: 10 | T38: 10 | V38: 10 | X38: 10
Q39: =SUM(Q29:Q38) -> 0 | S39: =SUM(S29:S38) -> 0 | U39: =SUM(U29:U38) -> 0 | W39: =SUM(W29:W38) -> 0 | Y39: =SUM(Y29:Y38) -> 0
F40: Datum: | H40: 46978 | I40: Terug naar Dag 1
A41: 1 | C41: 1 | E41: 1 | G41: 1 | I41: 1 | L41: Totaal | M41: =SUM(B51:J51) -> 0 | U41: Datum: | W41: 46978 | X41: Terug naar Dag 1
A42: 2 | C42: 2 | E42: 2 | G42: 2 | I42: 2 | L42: Laagste | M42: =MIN(B51:J51) -> 0 | P42: 1 | R42: 1 | T42: 1 | V42: 1 | X42: 1 | AA42: Totaal | AB42: =SUM(Q52:Y52) -> 0
...

Sheet Grafiek
J2: Datum | K2: Average | L2: Hoogste | M2: Laagste
J3: =Score!M7 -> dd/mm/jjjj | K3: =Score!M6 -> 0 | L3: =Score!M4 -> 0 | M3: =Score!M3 -> 0
J4: 45555 | K4: 75.2 | L4: 900 | M4: 520
J5: 45562 | K5: 74.2
A31: Copyright © 2024 Dartcoaching.nl All rights reserved. Alle rechten voorbehouden.
